Workbook

Sheet Management summary
A1: Management summary
A3: KPI
A5: Počet zákazníků celkem | B5: Podíl ověřených zákazníků | C5: Průměrný first_deposit_amount | D5: Mediánový first_deposit_amount | E5: Průměrný gross_revenue_90d | F5: Mediánový gross_revenue_90d | G5: Podíl aktivních zákazníků
A6: =COUNTA(Customers!A4:A15) -> 10 | B6: =COUNTIF(Customers!G4:G15,"1")/COUNTA(Customers!A4:A15) -> 0.8 | C6: =AVERAGE(Customers!H4:H15) -> 755 | D6: =MEDIAN(Customers!H4:H15) -> 500 | E6: =AVERAGE(Activity_90d!D4:D15) -> 934.5 | F6: =MEDIAN(Activity_90d!D4:D15) -> 270 | G6: =COUNTIF(Activity_90d!I4:I15,"<=30")/COUNTA(Customers!A4:A15) -> 0.8
A8: „Z celkových 12 zákazníků je 83 % ověřených a 83 % aktivních, což naznačuje relativně vysokou míru aktivace i verifikace v rámci vzorku.
A9: Průměrný first deposit činí 771 Kč, medián 550 Kč. U gross revenue je rozdíl mezi průměrem a mediánem výraznější (929 Kč vs. 375 Kč), což naznačuje, že celkový výnos je ovlivněn menší skupinou hodnotnějších zákazníků.“
A10: Nicméně vzorek dat je malý tak bych to tak silně nehodnotila.
A32: „Podle počtu zákazníků vede PPC, následované CRM. | F32: „Zatímco podle počtu zákazníků je nejsilnějším akvizičním kanálem PPC, podle hrubého výnosu za 90 dní vychází nejlépe CRM.
A33: Na 3. místě je shoda mezi Affiliate a Organic, proto se ve výstupu zobrazují 4 kanály.“ | F33: To naznačuje, že CRM přivádí nebo aktivuje hodnotnější zákazníky, i když v menším objemu než PPC.“
A36: Hlavní insight: PPC přivádí více zákazníků, ale CRM přináší vyšší hodnotu
A39: Segmentace
A58: „Segment High value má nejvyšší průměrný hrubý výnos i nejvyšší průměrný počet sázek, takže jde o nejhodnotnější skupinu zákazníků.
A59: Segment Inactive nevykazuje žádnou aktivitu a představuje prostor pro reaktivační kampaň.
A60: Segment Regular tvoří největší část vzorku a představuje běžně aktivní zákazníky se střední hodnotou.“
A63: „Na základě aktivity za posledních 90 dní jsem rozdělila zákazníky do tří segmentů: Inactive, Regular a High value.
A64: Segment High value tvoří 4 zákazníci a vykazuje nejvyšší průměrný počet sázek i nejvyšší průměrný hrubý výnos, zároveň jde o čerstvě aktivní zákazníky. S
A65: Segment Regular je nejpočetnější a představuje běžně aktivní zákazníky se střední hodnotou.
A66: Segment Inactive nevykazuje žádnou aktivitu ani výnos a byl naposledy aktivní v průměru před 90 dny, proto by dávalo smysl zvážit reaktivační kampaň.“
A68: „průměr plní zadání, ale kvůli odlehlým hodnotám jsem doplnila i medián pro robustnější interpretaci.“ | F68: Median Gross revenue 90 d | H68: 375
A70: Hlavní insight: Segment High value je menší, ale výrazně hodnotnější než segment Regular.
A72: A/B Testování
A74: Varianta A v A/B testu vychází lépe téměř ve všech klíčových metrikách.
A76: GROUP | B76: Open rate | C76: Click rate | D76: Deposit rate | E76: Bet rate | F76: Avg gross_revenue_7d | G76: Unsubscribe rate
A77: A | B77: =AVERAGEIF(Campaign_AB!B$2:B$13,"A",Campaign_AB!D$2:D$13) -> 0.83333333 | C77: =AVERAGEIF(Campaign_AB!B$2:B$13,"A",Campaign_AB!E$2:E$13) -> 0.66666667 | D77: =AVERAGEIF(Campaign_AB!B$2:B$13,"A",Campaign_AB!F$2:F$13) -> 0.66666667 | E77: =AVERAGEIF(Campaign_AB!B$2:B$13,"A",Campaign_AB!G$2:G$13) -> 0.83333333 | F77: =AVERAGEIF(Campaign_AB!B$2:B$13,"A",Campaign_AB!H$2:H$13) -> 185.83333 | G77: =AVERAGEIF(Campaign_AB!B$2:B$13,"A",Campaign_AB!I$2:I$13) -> 0.16666667
A78: B | B78: =AVERAGEIF(Campaign_AB!B$2:B$13,"B",Campaign_AB!D$2:D$13) -> 0.66666667 | C78: =AVERAGEIF(Campaign_AB!B$2:B$13,"B",Campaign_AB!E$2:E$13) -> 0.5 | D78: =AVERAGEIF(Campaign_AB!B$2:B$13,"B",Campaign_AB!F$2:F$13) -> 0.33333333 | E78: =AVERAGEIF(Campaign_AB!B$2:B$13,"B",Campaign_AB!G$2:G$13) -> 0.66666667 | F78: =AVERAGEIF(Campaign_AB!B$2:B$13,"B",Campaign_AB!H$2:H$13) -> 70.833333 | G78: =AVERAGEIF(Campaign_AB!B$2:B$13,"B",Campaign_AB!I$2:I$13) -> 0.16666667
A80: „Varianta A dosáhla vyššího open rate, click rate, deposit rate, bet rate i vyššího průměrného gross revenue za 7 dní.
A81: Unsubscribe rate je u obou variant stejný.
A82: Na základě dostupných dat bych proto doporučila preferovat variantu A.
A83: Výsledek je ale vhodné interpretovat opatrně kvůli malému vzorku.“
A85: Hlavní insight: Varianta A v A/B testu vychází lépe téměř ve všech klíčových metrikách.
A87: KORELACE A SOUVISLOSTI
A107: „Vybrala jsem vztah mezi active_days_90d a gross_revenue_90d, | F107: „Analyzovala jsem vztah mezi počtem aktivních dní a hrubým výnosem a dále mezi počtem sázek a hrubým výnosem
A108: protože předpokládám, že častější aktivita zákazníka souvisí s vyšší hodnotou. | F108: V obou případech vychází velmi silná pozitivní korelace, což naznačuje, že aktivnější zákazníci mají tendenci generovat vyšší hodnotu.
A109: Korelační koeficient ukazuje pozitivní vztah a scatter plot naznačuje, | F109: Korelace sama o sobě neznamená příčinný vztah.“
A110: že s rostoucím počtem aktivních dní roste i hrubý výnos.
A111: Korelace sama o sobě neprokazuje příčinu.“
A112: DOPORUČENÍ
A114: Zaměřit retenční péči na segment High value.
A115: Otestovat reaktivační kampaň na Inactive segment.
A116: Preferovat variantu A v další kampani.
...

Sheet Zadání
A1: List 1: Tasks
A3: Vlož tento text do buněk A1:A40:
A5: Cell | B5: Value
A6: A1 | B6: BUSINESS ANALYST CASE STUDY – FORTUNA
A7: A3 | B7: Časový limit: 120 minut
A8: A4 | B8: Pracujte pouze v Excelu. Zaměřte se na přesnost, přehlednost a business interpretaci.
A9: A6 | B9: Odevzdání:
A10: A7 | B10: 1) Vyplněný Excel soubor
A11: A8 | B11: 2) Krátké manažerské shrnutí na listu Output
A12: A10 | B12: Úkol 1 – Kontrola kvality dat
A13: A11 | B13: Identifikujte alespoň 3 problémy v kvalitě dat a uveďte, jak mohou ovlivnit interpretaci výsledků.
A14: A13 | B14: Úkol 2 – Základní KPI
A15: A14 | B15: Spočítejte:
A16: A15 | B16: - počet zákazníků celkem
... A33: A37 | B33: Nejde jen o výpočty, ale i o to, co z dat plyne pro business rozhodování.

Sheet legenda
A1: Customers
A2: Sloupec | B2: Význam
A3: customer_id | B3: Unikátní identifikátor zákazníka. Slouží ke spojení mezi jednotlivými listy.
A4: registration_date | B4: Datum registrace zákazníka do systému Fortuny.
A5: acquisition_channel | B5: Akviziční kanál, přes který zákazník přišel, např. PPC, CRM, Organic, Affiliate.
A6: region | B6: Region nebo město, ke kterému je zákazník přiřazen.
A7: device_type | B7: Převládající zařízení zákazníka při registraci nebo aktivitě, např. Mobile nebo Desktop.
A8: age_group | B8: Věková skupina zákazníka.
A9: is_verified | B9: Informace, zda je zákazník verifikovaný. Hodnota 1 = ano, 0 = ne.
A10: first_deposit_amount | B10: Výše prvního vkladu zákazníka v Kč. Pokud zákazník nevložil peníze, může být hodnota 0.
A11: days_to_first_bet | B11: Počet dní od registrace do první sázky nebo první herní aktivity. Vyšší hodnota znamená pomalejší aktivaci zákazníka.
A12: bonus_received | B12: Informace, zda zákazník obdržel registrační nebo marketingový bonus. Hodnota 1 = ano, 0 = ne.
A13: segment_prelabel | B13: Pomocné předběžné označení segmentu zákazníka. Slouží jen jako orientační proměnná, ne jako finální segmentace.
A15: Activity_90d
A16: Sloupec | B16: Význam
A17: customer_id | B17: Unikátní identifikátor zákazníka. Slouží ke spojení s listem Customers.
A18: bets_count_90d | B18: Počet sázek nebo herních aktivit zákazníka za posledních 90 dní.
A19: turnover_90d | B19: Celkový prosázený nebo protočený objem za posledních 90 dní v Kč.
A20: gross_revenue_90d | B20: Hrubý výnos za zákazníka za posledních 90 dní v Kč. Pro účely testu ber jako hlavní business hodnotu zákazníka.
A21: active_days_90d | B21: Počet dnů za posledních 90 dní, kdy byl zákazník aktivní.
A22: sports_bets_count | B22: Počet sportovních sázek za posledních 90 dní.
A23: casino_sessions_count | B23: Počet casino session nebo herních návštěv za posledních 90 dní.
A24: lottery_tickets_count | B24: Počet loterijních tiketů nebo loterijních aktivit za posledních 90 dní.
A25: last_active_days_ago | B25: Počet dní od poslední aktivity zákazníka. Nižší číslo znamená čerstvě aktivního zákazníka.
A26: deposits_count_90d | B26: Počet vkladů zákazníka za posledních 90 dní.
A27: avg_bet_amount | B27: Průměrná výše jedné sázky nebo herní aktivity v Kč.
A28: used_bonus_90d | B28: Informace, zda zákazník za posledních 90 dní využil bonus. Hodnota 1 = ano, 0 = ne.
A30: Campaign_AB
A31: Sloupec | B31: Význam
A32: customer_id | B32: Unikátní identifikátor zákazníka. Slouží ke spojení s ostatními listy.
A33: test_group | B33: Skupina v A/B testu. A = varianta A, B = varianta B.
A34: email_sent | B34: Informace, zda byl zákazníkovi e-mail skutečně odeslán. Hodnota 1 = ano, 0 = ne.
A35: email_opened | B35: Informace, zda zákazník e-mail otevřel. Hodnota 1 = ano, 0 = ne.
A36: email_clicked | B36: Informace, zda zákazník klikl na odkaz v e-mailu. Hodnota 1 = ano, 0 = ne.
A37: deposit_within_7d | B37: Informace, zda zákazník provedl vklad do 7 dní od odeslání kampaně. Hodnota 1 = ano, 0 = ne.
A38: bet_within_7d | B38: Informace, zda zákazník provedl sázku nebo herní aktivitu do 7 dní od odeslání kampaně. Hodnota 1 = ano, 0 = ne.
A39: gross_revenue_7d | B39: Hrubý výnos od zákazníka do 7 dní po kampani v Kč.
A40: unsubscribe | B40: Informace, zda se zákazník po kampani odhlásil z odběru. Hodnota 1 = ano, 0 = ne.
A41: send_hour | B41: Hodina odeslání e-mailu ve 24hodinovém formátu. Slouží pro základní posouzení vlivu času odeslání.

Sheet Customers
A1: customer_id | B1: registration_date | C1: acquisition_channel | D1: region | E1: device_type | F1: age_group | G1: is_verified | H1: first_deposit_amount | I1: days_to_first_bet | J1: bonus_received | K1: segment_prelabel | L1: gross_revenue_90d | N1: <----- přidaný sloupec přes XLOOKUP
A2: C001 | B2: 45931 | C2: PPC | D2: Praha | E2: Mobile | F2: 25-34 | G2: 1 | H2: 500 | I2: 1 | J2: 1 | K2: New | L2: =_xlfn.XLOOKUP(A2,Activity_90d!A2:A13,Activity_90d!D2:D13) -> 420
A3: C002 | B3: 45933 | C3: CRM | D3: Brno | E3: Desktop | F3: 35-44 | G3: 1 | H3: 1200 | I3: 0 | J3: 0 | K3: Regular | L3: =_xlfn.XLOOKUP(A3,Activity_90d!A3:A14,Activity_90d!D3:D14) -> 1380
A4: C003 | B4: 45935 | C4: Organic | D4: Ostrava | E4: Mobile | F4: 18-24 | G4: 0 | H4: 0 | I4: 999 | J4: 1 | K4: New | L4: =_xlfn.XLOOKUP(A4,Activity_90d!A4:A15,Activity_90d!D4:D15) -> 0
A5: C004 | B5: 45936 | C5: Affiliate | D5: Praha | E5: Mobile | F5: 25-34 | G5: 1 | H5: 300 | I5: 2 | J5: 1 | K5: Casual | L5: =_xlfn.XLOOKUP(A5,Activity_90d!A5:A16,Activity_90d!D5:D16) -> 180
A6: C005 | B6: 45938 | C6: PPC | D6: Plzeň | E6: Desktop | F6: 45-54 | G6: 1 | H6: 2000 | I6: 0 | J6: 0 | K6: VIP-like | L6: =_xlfn.XLOOKUP(A6,Activity_90d!A6:A17,Activity_90d!D6:D17) -> 3200
A7: C006 | B7: 45940 | C7: PPC | D7: Brno | E7: Mobile | F7: 25-34 | G7: 1 | H7: 700 | I7: 1 | J7: 1 | K7: Regular | L7: =_xlfn.XLOOKUP(A7,Activity_90d!A7:A18,Activity_90d!D7:D18) -> 510
A8: C007 | B8: 45942 | C8: PPC | D8: Praha | E8: Mobile | F8: 35-44 | G8: 1 | H8: 900 | I8: 3 | J8: 1 | K8: Regular | L8: =_xlfn.XLOOKUP(A8,Activity_90d!A8:A19,Activity_90d!D8:D19) -> 760
A9: C008 | B9: 45944 | C9: CRM | D9: Liberec | E9: Desktop | F9: 55+ | G9: 1 | H9: 150 | I9: 5 | J9: 0 | K9: Casual | L9: =_xlfn.XLOOKUP(A9,Activity_90d!A9:A20,Activity_90d!D9:D20) -> 55
A10: C009 | B10: 45945 | C10: Organic | D10: Brno | E10: Mobile | F10: 18-24 | G10: 0 | H10: 0 | I10: 999 | J10: 0 | K10: New | L10: =_xlfn.XLOOKUP(A10,Activity_90d!A10:A21,Activity_90d!D10:D21) -> 0
A11: C010 | B11: 45948 | C11: Affiliate | D11: Ostrava | E11: Desktop | F11: 25-34 | G11: 1 | H11: 400 | I11: 1 | J11: 1 | K11: Casual | L11: =_xlfn.XLOOKUP(A11,Activity_90d!A11:A22,Activity_90d!D11:D22) -> 210
A12: C011 | B12: 45950 | C12: CRM | D12: Praha | E12: Mobile | F12: 35-44 | G12: 1 | H12: 2500 | I12: 0 | J12: 0 | K12: VIP-like | L12: =_xlfn.XLOOKUP(A12,Activity_90d!A12:A23,Activity_90d!D12:D23) -> 4100
A13: C012 | B13: 45952 | C13: PPC | D13: Brno | E13: Mobile | F13: 25-34 | G13: 1 | H13: 600 | I13: 2 | J13: 1 | K13: Regular | L13: =_xlfn.XLOOKUP(A13,Activity_90d!A13:A24,Activity_90d!D13:D24) -> 330

Sheet Activity_90d
A1: customer_id | B1: bets_count_90d | C1: turnover_90d | D1: gross_revenue_90d | E1: active_days_90d | F1: sports_bets_count | G1: casino_sessions_count | H1: lottery_tickets_count | I1: last_active_days_ago | J1: deposits_count_90d | K1: avg_bet_amount | L1: used_bonus_90d
A2: C001 | B2: 12 | C2: 3400 | D2: 420 | E2: 8 | F2: 10 | G2: 2 | H2: 0 | I2: 3 | J2: 2 | K2: 283.3 | L2: 1
A3: C002 | B3: 34 | C3: 12500 | D3: 1380 | E3: 20 | F3: 28 | G3: 4 | H3: 2 | I3: 1 | J3: 5 | K3: 367.6 | L3: 0
A4: C003 | B4: 0 | C4: 0 | D4: 0 | E4: 0 | F4: 0 | G4: 0 | H4: 0 | I4: 90 | J4: 0 | K4: 0 | L4: 0
A5: C004 | B5: 6 | C5: 1500 | D5: 180 | E5: 4 | F5: 5 | G5: 1 | H5: 0 | I5: 12 | J5: 1 | K5: 250 | L5: 1
A6: C005 | B6: 55 | C6: 28000 | D6: 3200 | E6: 29 | F6: 40 | G6: 10 | H6: 5 | I6: 0 | J6: 8 | K6: 509.1 | L6: 0
A7: C006 | B7: 18 | C7: 4200 | D7: 510 | E7: 10 | F7: 14 | G7: 4 | H7: 0 | I7: 5 | J7: 3 | K7: 233.3 | L7: 1
A8: C007 | B8: 22 | C8: 6100 | D8: 760 | E8: 13 | F8: 18 | G8: 3 | H8: 1 | I8: 2 | J8: 4 | K8: 277.3 | L8: 1
A9: C008 | B9: 3 | C9: 500 | D9: 55 | E9: 2 | F9: 1 | G9: 0 | H9: 2 | I9: 27 | J9: 1 | K9: 166.7 | L9: 0
A10: C009 | B10: 0 | C10: 0 | D10: 0 | E10: 0 | F10: 0 | G10: 0 | H10: 0 | I10: 90 | J10: 0 | K10: 0 | L10: 0
A11: C010 | B11: 8 | C11: 1750 | D11: 210 | E11: 5 | F11: 6 | G11: 1 | H11: 1 | I11: 15 | J11: 2 | K11: 218.8 | L11: 1
A12: C011 | B12: 61 | C12: 35000 | D12: 4100 | E12: 33 | F12: 45 | G12: 12 | H12: 4 | I12: 0 | J12: 10 | K12: 573.8 | L12: 0
A13: C012 | B13: 14 | C13: 2900 | D13: 330 | E13: 7 | F13: 11 | G13: 2 | H13: 1 | I13: 8 | J13: 2 | K13: 207.1 | L13: 1

Sheet Campaign_AB
A1: customer_id | B1: test_group | C1: email_sent | D1: email_opened | E1: email_clicked | F1: deposit_within_7d | G1: bet_within_7d | H1: gross_revenue_7d | I1: unsubscribe | J1: send_hour | M1: Co si zapamatovat k A/B testu
A2: C001 | B2: A | C2: 1 | D2: 1 | E2: 1 | F2: 1 | G2: 1 | H2: 120 | I2: 0 | J2: 9
A3: C002 | B3: A | C3: 1 | D3: 1 | E3: 0 | F3: 1 | G3: 1 | H3: 210 | I3: 0 | J3: 9 | M3: Úplně jednoduše:
A4: C003 | B4: A | C4: 1 | D4: 0 | E4: 0 | F4: 0 | G4: 0 | H4: 0 | I4: 0 | J4: 9
A5: C004 | B5: A | C5: 1 | D5: 1 | E5: 1 | F5: 0 | G5: 1 | H5: 55 | I5: 1 | J5: 9 | M5: Postup
A6: C005 | B6: A | C6: 1 | D6: 1 | E6: 1 | F6: 1 | G6: 1 | H6: 340 | I6: 0 | J6: 9
A7: C006 | B7: B | C7: 1 | D7: 1 | E7: 1 | F7: 1 | G7: 1 | H7: 140 | I7: 0 | J7: 17 | M7: 1. rozděl A a B
A8: C007 | B8: B | C8: 1 | D8: 1 | E8: 1 | F8: 1 | G8: 1 | H8: 180 | I8: 0 | J8: 17 | M8: 2. spočítej metriky pro obě skupiny
A9: C008 | B9: B | C9: 1 | D9: 0 | E9: 0 | F9: 0 | G9: 0 | H9: 0 | I9: 0 | J9: 17 | M9: 3. porovnej je
A10: C009 | B10: B | C10: 1 | D10: 0 | E10: 0 | F10: 0 | G10: 0 | H10: 0 | I10: 1 | J10: 17 | M10: 4. rozhodni podle cíle kampaně
A11: C010 | B11: B | C11: 1 | D11: 1 | E11: 0 | F11: 0 | G11: 1 | H11: 40 | I11: 0 | J11: 17
A12: C011 | B12: A | C12: 1 | D12: 1 | E12: 1 | F12: 1 | G12: 1 | H12: 390 | I12: 0 | J12: 9 | M12: Myšlení
A13: C012 | B13: B | C13: 1 | D13: 1 | E13: 1 | F13: 0 | G13: 1 | H13: 65 | I13: 0 | J13: 17
M14: když je cíl otevření mailu → open rate
M15: když je cíl engagement → click rate
A16: GROUP | B16: Open rate | C16: Click rate | D16: Deposit rate | E16: Bet rate | F16: Avg gross_revenue_7d | G16: Unsubscribe rate | M16: když je cíl business výkon → deposit, bet, revenue
A17: A | B17: =AVERAGEIF(Campaign_AB!B$2:B$13,"A",Campaign_AB!D$2:D$13) -> 0.83333333 | C17: =AVERAGEIF(Campaign_AB!B$2:B$13,"A",Campaign_AB!E$2:E$13) -> 0.66666667 | D17: =AVERAGEIF(Campaign_AB!B$2:B$13,"A",Campaign_AB!F$2:F$13) -> 0.66666667 | E17: =AVERAGEIF(Campaign_AB!B$2:B$13,"A",Campaign_AB!G$2:G$13) -> 0.83333333 | F17: =AVERAGEIF(Campaign_AB!B$2:B$13,"A",Campaign_AB!H$2:H$13) -> 185.83333 | G17: =AVERAGEIF(Campaign_AB!B$2:B$13,"A",Campaign_AB!I$2:I$13) -> 0.16666667 | M17: unsubscribe sleduješ jako negativní efekt
A18: B | B18: =AVERAGEIF(Campaign_AB!B$2:B$13,"B",Campaign_AB!D$2:D$13) -> 0.66666667 | C18: =AVERAGEIF(Campaign_AB!B$2:B$13,"B",Campaign_AB!E$2:E$13) -> 0.5 | D18: =AVERAGEIF(Campaign_AB!B$2:B$13,"B",Campaign_AB!F$2:F$13) -> 0.33333333 | E18: =AVERAGEIF(Campaign_AB!B$2:B$13,"B",Campaign_AB!G$2:G$13) -> 0.66666667 | F18: =AVERAGEIF(Campaign_AB!B$2:B$13,"B",Campaign_AB!H$2:H$13) -> 70.833333 | G18: =AVERAGEIF(Campaign_AB!B$2:B$13,"B",Campaign_AB!I$2:I$13) -> 0.16666667
A20: „Varianta A dosáhla vyššího open rate, click rate, deposit rate, bet rate i vyššího průměrného gross revenue za 7 dní.
A21: Unsubscribe rate je u obou variant stejný.
A22: Na základě dostupných dat bych proto doporučila preferovat variantu A.
A23: Výsledek je ale vhodné interpretovat opatrně kvůli malému vzorku.“

Sheet č.1_ úkol 
A1: ÚKOL 1
A3: 1. „V datech jsou nekonzistentně pojmenované akviziční kanály, například PPC, ppc a Paid Search. Pokud jde o stejný typ zdroje, může to zkreslit porovnání výkonu kanálů i jejich podíl na revenue.“
A5: 2. Zákazníci bez prvního vkladu a s extrémní hodnotou days_to_first_bet = 999
A6: first_deposit_amount = 0
A7: days_to_first_bet = 999
A8: To je spíš technická placeholder hodnota než reálný počet dní.
A10: Jak to ovlivní interpretaci
A12: průměr days_to_first_bet bude uměle nafouknutý
A13: můžeš dojít k chybnému závěru, že aktivace zákazníků je extrémně pomalá
A14: pro statistiku a korelaci je to problematické, protože 999 není běžná hodnota chování
A16: Hodnota 999 u days_to_first_bet pravděpodobně slouží jako náhradní hodnota pro zákazníka bez první aktivity. Pokud by byla započtena do běžných výpočtů, mohla by výrazně zkreslit průměr i korelační analýzu.“
A18: 3. Možná logická nekonzistence v kampani
... A66: V obou případech vychází velmi silná pozitivní korelace, což naznačuje, že aktivnější zákazníci mají tendenci generovat vyšší hodnotu. Výsledek ale interpretuji opatrně, protože korelace sama o sobě neznamená příčinný vztah.“

Sheet KPI
A1: KPI
A3: Počet zákazníků celkem | B3: Podíl ověřených zákazníků | C3: Průměrný first_deposit_amount | D3: Mediánový first_deposit_amount | E3: Průměrný gross_revenue_90d | F3: Mediánový gross_revenue_90d | G3: Podíl aktivních zákazníků
A4: =COUNTA(Customers!A2:A13) -> 12 | B4: =COUNTIF(Customers!G2:G13,"1")/COUNTA(Customers!A2:A13) -> 0.83333333 | C4: =AVERAGE(Customers!H2:H13) -> 770.83333 | D4: =MEDIAN(Customers!H2:H13) -> 550 | E4: =AVERAGE(Activity_90d!D2:D13) -> 928.75 | F4: =MEDIAN(Activity_90d!D2:D13) -> 375 | G4: =COUNTIF(Activity_90d!I2:I13,"<=30")/COUNTA(Customers!A2:A13) -> 0.83333333
A7: „Z celkových 12 zákazníků je 83 % ověřených a 83 % aktivních, což naznačuje relativně vysokou míru aktivace i verifikace v rámci vzorku.
A8: Průměrný first deposit činí 771 Kč, medián 550 Kč. U gross revenue je rozdíl mezi průměrem a mediánem výraznější (929 Kč vs. 375 Kč), což naznačuje, že celkový výnos je ovlivněn menší skupinou hodnotnějších zákazníků.“
A9: Nicméně vzorek dat je malý tak bych to tak silně nehodnotila.
A10: Top 3 akviziční kanály podle počtu zákazníků | F10: Top 3 akviziční kanály podle hrubého výnosu od zákazníka do 90 dní po kampani v Kč.
A12: Row Labels | B12: Count of customer_id
A13: PPC | B13: 5
A14: CRM | B14: 3
A15: Affiliate | B15: 2 | F15: Row Labels | G15: Sum of gross_revenue_90d
A16: Organic | B16: 2 | F16: CRM | G16: 5535
A17: Grand Total | B17: 12 | F17: PPC | G17: 5220
F18: Affiliate | G18: 390
F19: Grand Total | G19: 11145
F30: pozn: musíme přes xlookup přesunout ze záložky Activity_90d hodnoty sloupce gross_revenue_90d, než vytvoříme pivot tabulku.
A31: „Podle počtu zákazníků vede PPC, následované CRM.
A32: Na 3. místě je shoda mezi Affiliate a Organic, proto se ve výstupu zobrazují 4 kanály.“ | F32: „Zatímco podle počtu zákazníků je nejsilnějším akvizičním kanálem PPC, podle hrubého výnosu za 90 dní vychází nejlépe CRM.
F33: To naznačuje, že CRM přivádí nebo aktivuje hodnotnější zákazníky, i když v menším objemu než PPC.“
F35: hlavní insight: PPC přivádí více zákazníků, ale CRM přináší vyšší hodnotu

Sheet č.3_Segmentace zákazníků
A1: customer_id | B1: bets_count_90d | C1: gross_revenue_90d | D1: last_active_days_ago | E1: Segment
A2: C001 | B2: 12 | C2: 420 | D2: 3 | E2: =IF(B2=0,"Inactive",IF(OR(B2>=20,C2>=1000),"High value","Regular")) -> Regular | G2: Segment | H2: Průměrný hrubý výnos | K2: Median Gross revenue 90 d
A3: C002 | B3: 34 | C3: 1380 | D3: 1 | E3: =IF(B3=0,"Inactive",IF(OR(B3>=20,C3>=1000),"High value","Regular")) -> High value | G3: High value | H3: 2360 | K3: =MEDIAN(C2:C13) -> 375
A4: C003 | B4: 0 | C4: 0 | D4: 90 | E4: =IF(B4=0,"Inactive",IF(OR(B4>=20,C4>=1000),"High value","Regular")) -> Inactive | G4: Regular | H4: 284.16667 | K4: „průměr plní zadání, ale kvůli odlehlým hodnotám jsem doplnila i medián pro robustnější interpretaci.“
A5: C004 | B5: 6 | C5: 180 | D5: 12 | E5: =IF(B5=0,"Inactive",IF(OR(B5>=20,C5>=1000),"High value","Regular")) -> Regular | G5: Inactive | H5: 0
A6: C005 | B6: 55 | C6: 3200 | D6: 0 | E6: =IF(B6=0,"Inactive",IF(OR(B6>=20,C6>=1000),"High value","Regular")) -> High value | G6: Grand Total | H6: 928.75
A7: C006 | B7: 18 | C7: 510 | D7: 5 | E7: =IF(B7=0,"Inactive",IF(OR(B7>=20,C7>=1000),"High value","Regular")) -> Regular
A8: C007 | B8: 22 | C8: 760 | D8: 2 | E8: =IF(B8=0,"Inactive",IF(OR(B8>=20,C8>=1000),"High value","Regular")) -> High value | G8: „Segment High value má nejvyšší průměrný hrubý výnos i nejvyšší průměrný počet sázek, takže jde o nejhodnotnější skupinu zákazníků.
A9: C008 | B9: 3 | C9: 55 | D9: 27 | E9: =IF(B9=0,"Inactive",IF(OR(B9>=20,C9>=1000),"High value","Regular")) -> Regular | G9: Segment Inactive nevykazuje žádnou aktivitu a představuje prostor pro reaktivační kampaň.
A10: C009 | B10: 0 | C10: 0 | D10: 90 | E10: =IF(B10=0,"Inactive",IF(OR(B10>=20,C10>=1000),"High value","Regular")) -> Inactive | G10: Segment Regular tvoří největší část vzorku a představuje běžně aktivní zákazníky se střední hodnotou.“
A11: C010 | B11: 8 | C11: 210 | D11: 15 | E11: =IF(B11=0,"Inactive",IF(OR(B11>=20,C11>=1000),"High value","Regular")) -> Regular
A12: C011 | B12: 61 | C12: 4100 | D12: 0 | E12: =IF(B12=0,"Inactive",IF(OR(B12>=20,C12>=1000),"High value","Regular")) -> High value
A13: C012 | B13: 14 | C13: 330 | D13: 8 | E13: =IF(B13=0,"Inactive",IF(OR(B13>=20,C13>=1000),"High value","Regular")) -> Regular | G13: „Na základě aktivity za posledních 90 dní jsem rozdělila zákazníky do tří segmentů: Inactive, Regular a High value.
G14: Segment High value tvoří 4 zákazníci a vykazuje nejvyšší průměrný počet sázek i nejvyšší průměrný hrubý výnos, zároveň jde o čerstvě aktivní zákazníky. S
A15: Segment | B15: Počet zákazníků | G15: Segment Regular je nejpočetnější a představuje běžně aktivní zákazníky se střední hodnotou.
A16: Regular | B16: 6 | G16: Segment Inactive nevykazuje žádnou aktivitu ani výnos a byl naposledy aktivní v průměru před 90 dny, proto by dávalo smysl zvážit reaktivační kampaň.“
A17: High value | B17: 4
A18: Inactive | B18: 2
A19: Grand Total | B19: 12

Sheet č.5 Korelace
A2: Korelace a souvislosti
A4: Vyberte 2–3 proměnné a zhodnoťte, zda mezi nimi vidíte zajímavý vztah. Použijte korelační koeficient, graf a krátký komentář.
A5: Zjišťujeme jestli je závislost mezi aktivními dny a hrubým výnosem na zákazníka. Čím víc aktivních dní, tím vyšší revenue?
A6: active_days_90d | B6: gross_revenue_90d | D6: Korelace
A7: 8 | B7: 420 | D7: =CORREL(A5:A18,B5:B18) -> 0.96576383
A8: 20 | B8: 1380
A9: 0 | B9: 0
A10: 4 | B10: 180
A11: 29 | B11: 3200
A12: 10 | B12: 510
A13: 13 | B13: 760
A14: 2 | B14: 55
A15: 0 | B15: 0
A16: 5 | B16: 210
A17: 33 | B17: 4100
A18: 7 | B18: 330
A20: Korelace se pohybuje blíže k číslu 1, což značí pozitivní vztah. Čili závislost.
A22: „Mezi počtem aktivních dní a gross revenue za 90 dní vidím silnou pozitivní souvislost. Zákazníci s vyšším počtem aktivních dní mají obvykle také vyšší hrubý výnos. Je ale potřeba dodat, že korelace neznamená kauzalitu.“
A23: Korelace sama o sobě neprokazuje kauzalitu.
A25: „Vybrala jsem vztah mezi active_days_90d a gross_revenue_90d, protože předpokládám, že častější aktivita zákazníka souvisí s vyšší hodnotou.
A26: Korelační koeficient ukazuje pozitivní vztah a scatter plot naznačuje, že s rostoucím počtem aktivních dní roste i hrubý výnos.
A27: Výsledek je ale vhodné interpretovat opatrně, protože korelace sama o sobě neprokazuje příčinu.“

Sheet č.5Korelace_b
A1: bets_count_90d | B1: gross_revenue_90d | D1: Korelace
A2: 12 | B2: 420 | D2: =CORREL(A2:A13,B2:B13) -> 0.97400007
A3: 34 | B3: 1380
A4: 0 | B4: 0
A5: 6 | B5: 180
A6: 55 | B6: 3200
A7: 18 | B7: 510
A8: 22 | B8: 760
A9: 3 | B9: 55
A10: 0 | B10: 0
A11: 8 | B11: 210
A12: 61 | B12: 4100
A13: 14 | B13: 330
A19: „Mezi počtem sázek za 90 dní a hrubým výnosem za 90 dní je velmi silná pozitivní korelace (r = 0,974).
A20: To naznačuje, že zákazníci s vyšší frekvencí sázek mají obvykle i vyšší hrubý výnos. Výsledek ale neprokazuje kauzalitu.“
A23: Důležitá poznámka
A25: Tahle korelace bude přirozeně vysoká, protože:
A27: více sázek často logicky vede k vyššímu revenue,
A28: takže je to spíš potvrzení očekávaného vztahu než překvapivý insight.
A31: „Analyzovala jsem vztah mezi počtem aktivních dní a hrubým výnosem a dále mezi počtem sázek a hrubým výnosem
A32: V obou případech vychází velmi silná pozitivní korelace, což naznačuje, že aktivnější zákazníci mají tendenci generovat vyšší hodnotu. Výsledek ale interpretuji opatrně, protože korelace sama o sobě neznamená příčinný vztah.“
